Workbook

Sheet DATA upload
A1: =Sheet1!A1 -> No | B1: =Sheet1!B1 -> Cabang Tujuan Order | C1: =Sheet1!C1 -> Customer | D1: =Sheet1!D1 -> order No Confins | E1: =Sheet1!E1 -> prospect No | F1: =Sheet1!F1 -> Source App | G1: =Sheet1!G1 -> agrmnt no | H1: =Sheet1!H1 -> application no | I1: =Sheet1!I1 -> cmo | J1: =Sheet1!K1 -> order input | K1: =Sheet1!L1 -> Status Date | L1: =Sheet1!M1 -> statusname | M1: =Sheet1!P1 -> Merk Asset | N1: =Sheet1!Q1 -> Tahun Asset | O1: =Sheet1!AB1 -> ntf amt | P1: =Sheet1!AD1 -> survey date | Q1: =Sheet1!AI1 -> Sales Agen ID | R1: =Sheet1!AJ1 -> Nama Sales Agen | S1: =Sheet1!AK1 -> Status Category | T1: =Sheet1!AL1 -> SOA | U1: Status Survey | V1: Type Agent | W1: Type Nasabah | X1: Summary Slik | Y1: Total installment
A2: =Sheet1!A2 -> 1 | B2: =Sheet1!B2 -> ALAM SUTERA | C2: =Sheet1!C2 -> SAKIRAN | D2: =Sheet1!D2 -> ODRNO2607010097 | E2: =Sheet1!E2 -> 838PRS20260702390 | F2: =Sheet1!F2 -> Sales Agent (SA) | G2: =Sheet1!G2 -> 8381032600023 | H2: =Sheet1!H2 -> 838APP20260700009 | I2: =Sheet1!I2 -> IBRAHIM AZIZ | J2: =Sheet1!K2 -> 46204.508 | K2: =Sheet1!L2 -> 46207.535 | L2: =Sheet1!M2 -> Go Live | M2: =Sheet1!P2 -> TOYOTA | N2: =Sheet1!Q2 -> 2022 | O2: =Sheet1!AB2 -> 216083000 | P2: =Sheet1!AD2 -> 46205 | Q2: =Sheet1!AI2 -> DONNIE PRASTIYO-526010 | R2: =Sheet1!AJ2 | S2: =Sheet1!AK2 -> Golive | T2: =Sheet1!AL2 -> SA | U2: =IF(H2=0,0,"Done Survey") -> Done Survey | V2: External | W2: New Customer
A3: =Sheet1!A3 -> 2 | B3: =Sheet1!B3 -> ALAM SUTERA | C3: =Sheet1!C3 -> GATOT WARDONO | D3: =Sheet1!D3 -> ODRNO2607010131 | E3: =Sheet1!E3 -> 838PRS20260702392 | F3: =Sheet1!F3 -> LandingPage | G3: =Sheet1!G3 -> 0 | H3: =Sheet1!H3 -> 0 | I3: =Sheet1!I3 -> IBRAHIM AZIZ | J3: =Sheet1!K3 -> 46204.62 | K3: =Sheet1!L3 -> 46212.333 | L3: =Sheet1!M3 -> Prospect Cancel | M3: =Sheet1!P3 -> SUZUKI | N3: =Sheet1!Q3 -> 2011 | O3: =Sheet1!AB3 -> 0 | P3: =Sheet1!AD3 -> 0 | Q3: =Sheet1!AI3 -> 0 | R3: =Sheet1!AJ3 -> 0 | S3: =Sheet1!AK3 -> Cancel | T3: =Sheet1!AL3 -> SA | U3: =IF(H3=0,0,"Done Survey") -> 0 | V3: Internal | W3: Repeat Order
A4: =Sheet1!A4 -> 3 | B4: =Sheet1!B4 -> BANDUNG | C4: =Sheet1!C4 -> ARIE ARLIAN DARLIANA | D4: =Sheet1!D4 -> ODRNO2607010064 | E4: =Sheet1!E4 -> 813PRS20260705019 | F4: =Sheet1!F4 -> Sales Agent (SA) | G4: =Sheet1!G4 -> 0 | H4: =Sheet1!H4 -> 0 | I4: =Sheet1!I4 -> RAMDHAN FIRMANSYAH | J4: =Sheet1!K4 -> 46204.456 | K4: =Sheet1!L4 -> 46212.333 | L4: =Sheet1!M4 -> Prospect Cancel | M4: =Sheet1!P4 -> DAIHATSU | N4: =Sheet1!Q4 -> 2016 | O4: =Sheet1!AB4 -> 0 | P4: =Sheet1!AD4 -> 0 | Q4: =Sheet1!AI4 -> SONI SOMANTRI-126214 | R4: =Sheet1!AJ4 | S4: =Sheet1!AK4 -> Cancel | T4: =Sheet1!AL4 -> SA | U4: =IF(H4=0,0,"Done Survey") -> 0
A5: =Sheet1!A5 -> 4 | B5: =Sheet1!B5 -> BANDUNG | C5: =Sheet1!C5 -> SITI FATIMAH | D5: =Sheet1!D5 -> ODRNO2607010086 | E5: =Sheet1!E5 -> 813PRS20260705023 | F5: =Sheet1!F5 -> Sales Agent (SA) | G5: =Sheet1!G5 -> 0 | H5: =Sheet1!H5 -> 0 | I5: =Sheet1!I5 -> RAMDHAN FIRMANSYAH | J5: =Sheet1!K5 -> 46204.491 | K5: =Sheet1!L5 -> 46212.333 | L5: =Sheet1!M5 -> Prospect Cancel | M5: =Sheet1!P5 -> TOYOTA | N5: =Sheet1!Q5 -> 2016 | O5: =Sheet1!AB5 -> 0 | P5: =Sheet1!AD5 -> 0 | Q5: =Sheet1!AI5 -> ARIF NUR ALIM HIDAYAT-126022 | R5: =Sheet1!AJ5 | S5: =Sheet1!AK5 -> Cancel | T5: =Sheet1!AL5 -> SA | U5: =IF(H5=0,0,"Done Survey") -> 0
A6: =Sheet1!A6 -> 5 | B6: =Sheet1!B6 -> BATAM | C6: =Sheet1!C6 -> Ade Irma Nurjannah | D6: =Sheet1!D6 -> ODRNO2607010021 | E6: =Sheet1!E6 -> 806PRS20260701974 | F6: =Sheet1!F6 -> LandingPage | G6: =Sheet1!G6 -> 0 | H6: =Sheet1!H6 -> 0 | I6: =Sheet1!I6 -> AGUNG SETIAWAN FATTAH | J6: =Sheet1!K6 -> 46204.369 | K6: =Sheet1!L6 -> 46204.485 | L6: =Sheet1!M6 -> Prospect Cancel | M6: =Sheet1!P6 -> TOYOTA | N6: =Sheet1!Q6 -> 2022 | O6: =Sheet1!AB6 -> 0 | P6: =Sheet1!AD6 -> 0 | Q6: =Sheet1!AI6 -> 0 | R6: =Sheet1!AJ6 -> 0 | S6: =Sheet1!AK6 -> Cancel | T6: =Sheet1!AL6 -> SA | U6: =IF(H6=0,0,"Done Survey") -> 0
A7: =Sheet1!A7 -> 6 | B7: =Sheet1!B7 -> BEKASI | C7: =Sheet1!C7 -> SRIYONO | D7: =Sheet1!D7 -> ODRNO2607010094 | E7: =Sheet1!E7 -> 811PRS20260704433 | F7: =Sheet1!F7 -> Sales Agent (SA) | G7: =Sheet1!G7 -> 8111022600026 | H7: =Sheet1!H7 -> 811APP20260700035 | I7: =Sheet1!I7 -> KURNIAWAN ARIBOWO | J7: =Sheet1!K7 -> 46204.501 | K7: =Sheet1!L7 -> 46213.39 | L7: =Sheet1!M7 -> Go Live | M7: =Sheet1!P7 -> DAIHATSU | N7: =Sheet1!Q7 -> 2018 | O7: =Sheet1!AB7 -> 108220074 | P7: =Sheet1!AD7 -> 46212 | Q7: =Sheet1!AI7 -> BAGJA SANJAYA-126014 | R7: =Sheet1!AJ7 | S7: =Sheet1!AK7 -> Golive | T7: =Sheet1!AL7 -> SA | U7: =IF(H7=0,0,"Done Survey") -> Done Survey
A8: =Sheet1!A8 -> 7 | B8: =Sheet1!B8 -> BEKASI | C8: =Sheet1!C8 -> SAFARUDIN | D8: =Sheet1!D8 -> ODRNO2607010110 | E8: =Sheet1!E8 -> 811PRS20260704439 | F8: =Sheet1!F8 -> LandingPage | G8: =Sheet1!G8 -> 0 | H8: =Sheet1!H8 -> 0 | I8: =Sheet1!I8 -> KURNIAWAN ARIBOWO | J8: =Sheet1!K8 -> 46204.53 | K8: =Sheet1!L8 -> 46212.333 | L8: =Sheet1!M8 -> Prospect Cancel | M8: =Sheet1!P8 -> DAIHATSU | N8: =Sheet1!Q8 -> 2022 | O8: =Sheet1!AB8 -> 0 | P8: =Sheet1!AD8 -> 0 | Q8: =Sheet1!AI8 -> 0 | R8: =Sheet1!AJ8 -> 0 | S8: =Sheet1!AK8 -> Cancel | T8: =Sheet1!AL8 -> SA | U8: =IF(H8=0,0,"Done Survey") -> 0
A9: =Sheet1!A9 -> 8 | B9: =Sheet1!B9 -> BEKASI | C9: =Sheet1!C9 -> VERDY THAIB | D9: =Sheet1!D9 -> ODRNO2607010173 | E9: =Sheet1!E9 -> 811PRS20260704455 | F9: =Sheet1!F9 -> Sales Agent (SA) | G9: =Sheet1!G9 -> 0 | H9: =Sheet1!H9 -> 0 | I9: =Sheet1!I9 -> KURNIAWAN ARIBOWO | J9: =Sheet1!K9 -> 46204.745 | K9: =Sheet1!L9 -> 46212.333 | L9: =Sheet1!M9 -> Prospect Cancel | M9: =Sheet1!P9 -> TOYOTA | N9: =Sheet1!Q9 -> 2014 | O9: =Sheet1!AB9 -> 0 | P9: =Sheet1!AD9 -> 0 | Q9: =Sheet1!AI9 -> JEFFRI STAVANUS M-326087 | R9: =Sheet1!AJ9 | S9: =Sheet1!AK9 -> Cancel | T9: =Sheet1!AL9 -> SA | U9: =IF(H9=0,0,"Done Survey") -> 0
A10: =Sheet1!A10 -> 9 | B10: =Sheet1!B10 -> KEMAYORAN | C10: =Sheet1!C10 -> Laurent Putra | D10: =Sheet1!D10 -> ODRNO2607010078 | E10: =Sheet1!E10 -> 801PRS20260700845 | F10: =Sheet1!F10 -> Sales Agent (SA) | G10: =Sheet1!G10 -> 0 | H10: =Sheet1!H10 -> 0 | I10: =Sheet1!I10 -> MUHAMMAD RIZQY KEMAL | J10: =Sheet1!K10 -> 46204.484 | K10: =Sheet1!L10 -> 46204.497 | L10: =Sheet1!M10 -> Prospect Cancel | M10: =Sheet1!P10 -> TOYOTA | N10: =Sheet1!Q10 -> 2022 | O10: =Sheet1!AB10 -> 0 | P10: =Sheet1!AD10 -> 0 | Q10: =Sheet1!AI10 -> BANDUNG PRASETYO-0626069 | R10: =Sheet1!AJ10 | S10: =Sheet1!AK10 -> Cancel | T10: =Sheet1!AL10 -> SA | U10: =IF(H10=0,0,"Done Survey") -> 0
A11: =Sheet1!A11 -> 10 | B11: =Sheet1!B11 -> KEMAYORAN | C11: =Sheet1!C11 -> Supriantono Syahputra Wijaya | D11: =Sheet1!D11 -> ODRNO2607010136 | E11: =Sheet1!E11 -> 801PRS20260700850 | F11: =Sheet1!F11 -> Sales Agent (SA) | G11: =Sheet1!G11 -> 0 | H11: =Sheet1!H11 -> 0 | I11: =Sheet1!I11 -> MUHAMMAD RIZQY KEMAL | J11: =Sheet1!K11 -> 46204.638 | K11: =Sheet1!L11 -> 46212.333 | L11: =Sheet1!M11 -> Prospect Cancel | M11: =Sheet1!P11 -> DAIHATSU | N11: =Sheet1!Q11 -> 2011 | O11: =Sheet1!AB11 -> 0 | P11: =Sheet1!AD11 -> 0 | Q11: =Sheet1!AI11 -> ANTON RIA YANANTO-226215 | R11: =Sheet1!AJ11 | S11: =Sheet1!AK11 -> Cancel | T11: =Sheet1!AL11 -> SA | U11: =IF(H11=0,0,"Done Survey") -> 0
A12: =Sheet1!A12 -> 11 | B12: =Sheet1!B12 -> MANADO | C12: =Sheet1!C12 -> ANTONIUS WILLEM RAWUNG | D12: =Sheet1!D12 -> ODRNO2607010013 | E12: =Sheet1!E12 -> 828PRS20260700327 | F12: =Sheet1!F12 -> Sales Agent (SA) | G12: =Sheet1!G12 -> 0 | H12: =Sheet1!H12 -> 0 | I12: =Sheet1!I12 -> BATIN E TUWUILU | J12: =Sheet1!K12 -> 46204.353 | K12: =Sheet1!L12 -> 46212.333 | L12: =Sheet1!M12 -> Prospect Cancel | M12: =Sheet1!P12 -> NISSAN | N12: =Sheet1!Q12 -> 2021 | O12: =Sheet1!AB12 -> 0 | P12: =Sheet1!AD12 -> 0 | Q12: =Sheet1!AI12 -> PINGKAN IRENE HERMANUS-226129 | R12: =Sheet1!AJ12 | S12: =Sheet1!AK12 -> Cancel | T12: =Sheet1!AL12 -> SA | U12: =IF(H12=0,0,"Done Survey") -> 0
A13: =Sheet1!A13 -> 12 | B13: =Sheet1!B13 -> MANADO | C13: =Sheet1!C13 -> OLDI OLIVER ROMPIS | D13: =Sheet1!D13 -> ODRNO2607010014 | E13: =Sheet1!E13 -> 828PRS20260700328 | F13: =Sheet1!F13 -> Sales Agent (SA) | G13: =Sheet1!G13 -> 0 | H13: =Sheet1!H13 -> 0 | I13: =Sheet1!I13 -> BATIN E TUWUILU | J13: =Sheet1!K13 -> 46204.357 | K13: =Sheet1!L13 -> 46204.363 | L13: =Sheet1!M13 -> Prospect Cancel | M13: =Sheet1!P13 -> TOYOTA | N13: =Sheet1!Q13 -> 2015 | O13: =Sheet1!AB13 -> 0 | P13: =Sheet1!AD13 -> 0 | Q13: =Sheet1!AI13 -> PINGKAN IRENE HERMANUS-226129 | R13: =Sheet1!AJ13 | S13: =Sheet1!AK13 -> Cancel | T13: =Sheet1!AL13 -> SA | U13: =IF(H13=0,0,"Done Survey") -> 0
A14: =Sheet1!A14 -> 13 | B14: =Sheet1!B14 -> MANADO | C14: =Sheet1!C14 -> JENDRY INDRO GEORGE KOJONGIAN | D14: =Sheet1!D14 -> ODRNO2607010017 | E14: =Sheet1!E14 -> 828PRS20260700329 | F14: =Sheet1!F14 -> Sales Agent (SA) | G14: =Sheet1!G14 -> 0 | H14: =Sheet1!H14 -> 0 | I14: =Sheet1!I14 -> BATIN E TUWUILU | J14: =Sheet1!K14 -> 46204.361 | K14: =Sheet1!L14 -> 46212.333 | L14: =Sheet1!M14 -> Prospect Cancel | M14: =Sheet1!P14 -> MITSUBISHI | N14: =Sheet1!Q14 -> 2019 | O14: =Sheet1!AB14 -> 0 | P14: =Sheet1!AD14 -> 0 | Q14: =Sheet1!AI14 -> PINGKAN IRENE HERMANUS-226129 | R14: =Sheet1!AJ14 | S14: =Sheet1!AK14 -> Cancel | T14: =Sheet1!AL14 -> SA | U14: =IF(H14=0,0,"Done Survey") -> 0
A15: =Sheet1!A15 -> 14 | B15: =Sheet1!B15 -> BANDUNG | C15: =Sheet1!C15 -> SANDI TRIYANA | D15: =Sheet1!D15 -> ODRNO2607020011 | E15: =Sheet1!E15 -> 813PRS20260705030 | F15: =Sheet1!F15 -> Sales Agent (SA) | G15: =Sheet1!G15 -> 0 | H15: =Sheet1!H15 -> 0 | I15: =Sheet1!I15 -> RAMDHAN FIRMANSYAH | J15: =Sheet1!K15 -> 46205.341 | K15: =Sheet1!L15 -> 46213.333 | L15: =Sheet1!M15 -> Prospect Cancel | M15: =Sheet1!P15 -> TOYOTA | N15: =Sheet1!Q15 -> 2016 | O15: =Sheet1!AB15 -> 0 | P15: =Sheet1!AD15 -> 0 | Q15: =Sheet1!AI15 -> ARIS YULIANSYAH HILMAN-126175 | R15: =Sheet1!AJ15 | S15: =Sheet1!AK15 -> Cancel | T15: =Sheet1!AL15 -> SA | U15: =IF(H15=0,0,"Done Survey") -> 0
... A485: =Sheet1!A485 -> 484 | B485: =Sheet1!B485 -> DENPASAR | C485: =Sheet1!C485 -> I MADE DWI ISWAYANA | D485: =Sheet1!D485 -> ODRNO2608030033 | E485: =Sheet1!E485 -> 821PRS20260800821 | F485: =Sheet1!F485 -> Sales Agent (SA) | G485: =Sheet1!G485 -> 0 | H485: =Sheet1!H485 -> 0 | I485: =Sheet1!I485 -> I MADE BAGUS PUTRA WIRAPASTIKA S I KOM | J485: =Sheet1!K485 -> 46237 | K485: =Sheet1!L485 -> 46237.351 | L485: =Sheet1!M485 -> New Data | M485: =Sheet1!P485 -> DAIHATSU | N485: =Sheet1!Q485 -> 2015 | O485: =Sheet1!AB485 -> 0 | P485: =Sheet1!AD485 -> 0 | Q485: =Sheet1!AI485 -> A A GEDE BAGUS PUTRA WIRAWAN-0626024 | R485: =Sheet1!AJ485 | S485: =Sheet1!AK485 -> In Proses | T485: =Sheet1!AL485 -> SA | U485: =IF(H485=0,0,"Done Survey") -> 0

Sheet Sheet1
A1: No | B1: Cabang Tujuan Order | C1: Customer | D1: order No Confins | E1: prospect No | F1: Source App | G1: agrmnt no | H1: application no | I1: cmo | J1: Nama Supplier | K1: order input | L1: Status Date | M1: statusname | N1: statusdesc | O1: asset Type | P1: Merk Asset | Q1: Tahun Asset | R1: user Prospect dashboard | S1: user Prospect Confins | T1: survey 1 name | U1: survey 2 name | V1: Recommended / Not Recommended | W1: isdki | X1: Kategori Ordef | Y1: Referantor Type | Z1: Product Offering Description | AA1: NIK | AB1: ntf amt | AC1: assignee | AD1: survey date | AE1: nopolisi (confins) | AF1: nopolisi (dashboard los) | AG1: suppl branch code | AH1: Supplier Category | AI1: Sales Agen ID | AJ1: Nama Sales Agen | AK1: Status Category | AL1: SOA | AM1: Date order in | AN1: Year | AO1: Month App In | AP1: Date Status | AQ1: Month Status | AR1: Type Agent | AS1: Type Nasabah | AT1: Summary Slik | AU1: Total installment | AV1: Update app in
A2: 1 | B2: ALAM SUTERA | C2: SAKIRAN | D2: ODRNO2607010097 | E2: 838PRS20260702390 | F2: Sales Agent (SA) | G2: 8381032600023 | H2: 838APP20260700009 | I2: IBRAHIM AZIZ | J2: PINJAMAN BU ANA | K2: 46204.508 | L2: 46207.535 | M2: Go Live | N2: Status Aplikasi sudah dilakukan Golive | O2: USED | P2: TOYOTA | Q2: 2022 | R2: automatic | S2: MUHLIS2 | V2: not survey / not survey | W2: DKI | X2: Form Order - CF Bu Ana | Y2: Sales Agent (SA) | Z2: PINJAMAN BU ANA PASSENGER SUMBER SALES AGENT PAKET SANTUY REBORN - MODAL USAHA | AA2: 3603020605690001 | AB2: 216083000 | AC2: MUHLIS2 | AD2: 46205 | AE2: A 135 WC | AF2: B | AG2: MULTIGUNA JASA | AI2: DONNIE PRASTIYO-526010 | AK2: Golive | AL2: SA | AM2: 1 | AN2: 2026 | AO2: July | AP2: 4 | AQ2: July | AR2: External | AS2: New Customer
A3: 2 | B3: ALAM SUTERA | C3: GATOT WARDONO | D3: ODRNO2607010131 | E3: 838PRS20260702392 | F3: LandingPage | I3: IBRAHIM AZIZ | K3: 46204.62 | L3: 46212.333 | M3: Prospect Cancel | N3: Status Cancel Prospect | O3: USED | P3: SUZUKI | Q3: 2011 | V3: not survey / not survey | W3: DKI | X3: Form Order - CF Bu Ana | Y3: LandingPage | AA3: 3173080308750007 | AF3: B 1977 JVH | AK3: Cancel | AL3: SA | AM3: 1 | AN3: 2026 | AO3: July | AP3: 9 | AQ3: July | AR3: Internal | AS3: Repeat Order
A4: 3 | B4: BANDUNG | C4: ARIE ARLIAN DARLIANA | D4: ODRNO2607010064 | E4: 813PRS20260705019 | F4: Sales Agent (SA) | I4: RAMDHAN FIRMANSYAH | K4: 46204.456 | L4: 46212.333 | M4: Prospect Cancel | N4: Status Cancel Prospect | O4: USED | P4: DAIHATSU | Q4: 2016 | V4: not survey / not survey | W4: NON DKI | X4: Form Order - CF Bu Ana | Y4: Sales Agent (SA) | AA4: 3204380407860015 | AF4: 0 | AI4: SONI SOMANTRI-126214 | AK4: Cancel | AL4: SA | AM4: 1 | AN4: 2026 | AO4: July | AP4: 9 | AQ4: July
A5: 4 | B5: BANDUNG | C5: SITI FATIMAH | D5: ODRNO2607010086 | E5: 813PRS20260705023 | F5: Sales Agent (SA) | I5: RAMDHAN FIRMANSYAH | K5: 46204.491 | L5: 46212.333 | M5: Prospect Cancel | N5: Status Cancel Prospect | O5: USED | P5: TOYOTA | Q5: 2016 | V5: not survey / not survey | W5: NON DKI | X5: Form Order - CF Bu Ana | Y5: Sales Agent (SA) | AA5: 3273224908910002 | AF5: 0 | AI5: ARIF NUR ALIM HIDAYAT-126022 | AK5: Cancel | AL5: SA | AM5: 1 | AN5: 2026 | AO5: July | AP5: 9 | AQ5: July
A6: 5 | B6: BATAM | C6: Ade Irma Nurjannah | D6: ODRNO2607010021 | E6: 806PRS20260701974 | F6: LandingPage | I6: AGUNG SETIAWAN FATTAH | K6: 46204.369 | L6: 46204.485 | M6: Prospect Cancel | N6: Status Cancel Prospect | O6: USED | P6: TOYOTA | Q6: 2022 | R6: setyo.yulianto | V6: not survey / not survey | W6: NON DKI | X6: Form Order - CF Bu Ana | Y6: LandingPage | AA6: 1219064809950004 | AF6: 0 | AK6: Cancel | AL6: SA | AM6: 1 | AN6: 2026 | AO6: July | AP6: 1 | AQ6: July
A7: 6 | B7: BEKASI | C7: SRIYONO | D7: ODRNO2607010094 | E7: 811PRS20260704433 | F7: Sales Agent (SA) | G7: 8111022600026 | H7: 811APP20260700035 | I7: KURNIAWAN ARIBOWO | J7: PINJAMAN BU ANA | K7: 46204.501 | L7: 46213.39 | M7: Go Live | N7: Status Aplikasi sudah dilakukan Golive | O7: USED | P7: DAIHATSU | Q7: 2018 | R7: automatic | S7: MUHLIS2 | V7: not survey / not survey | W7: DKI | X7: Form Order - CF Bu Ana | Y7: Sales Agent (SA) | Z7: PINJAMAN BU ANA PASSENGER SUMBER SALES AGENT PAKET SANTUY REBORN | AA7: 3510012801790003 | AB7: 108220074 | AC7: MUHLIS2 | AD7: 46212 | AE7: B 2171 BOO | AF7: b | AG7: MULTIGUNA JASA | AI7: BAGJA SANJAYA-126014 | AK7: Golive | AL7: SA | AM7: 1 | AN7: 2026 | AO7: July | AP7: 10 | AQ7: July
A8: 7 | B8: BEKASI | C8: SAFARUDIN | D8: ODRNO2607010110 | E8: 811PRS20260704439 | F8: LandingPage | I8: KURNIAWAN ARIBOWO | K8: 46204.53 | L8: 46212.333 | M8: Prospect Cancel | N8: Status Cancel Prospect | O8: USED | P8: DAIHATSU | Q8: 2022 | V8: not survey / not survey | W8: DKI | X8: Form Order - CF Bu Ana | Y8: LandingPage | AA8: 3215132604740003 | AF8: b | AK8: Cancel | AL8: SA | AM8: 1 | AN8: 2026 | AO8: July | AP8: 9 | AQ8: July
A9: 8 | B9: BEKASI | C9: VERDY THAIB | D9: ODRNO2607010173 | E9: 811PRS20260704455 | F9: Sales Agent (SA) | I9: KURNIAWAN ARIBOWO | K9: 46204.745 | L9: 46212.333 | M9: Prospect Cancel | N9: Status Cancel Prospect | O9: USED | P9: TOYOTA | Q9: 2014 | V9: not survey / not survey | W9: DKI | X9: Form Order - CF Bu Ana | Y9: Sales Agent (SA) | AA9: 3174010705790006 | AF9: b | AI9: JEFFRI STAVANUS M-326087 | AK9: Cancel | AL9: SA | AM9: 1 | AN9: 2026 | AO9: July | AP9: 9 | AQ9: July
A10: 9 | B10: KEMAYORAN | C10: Laurent Putra | D10: ODRNO2607010078 | E10: 801PRS20260700845 | F10: Sales Agent (SA) | I10: MUHAMMAD RIZQY KEMAL | K10: 46204.484 | L10: 46204.497 | M10: Prospect Cancel | N10: Status Cancel Prospect | O10: USED | P10: TOYOTA | Q10: 2022 | R10: automatic | V10: not survey / not survey | W10: DKI | X10: Form Order - CF Bu Ana | Y10: Sales Agent (SA) | AA10: 3172061112950003 | AF10: b | AI10: BANDUNG PRASETYO-0626069 | AK10: Cancel | AL10: SA | AM10: 1 | AN10: 2026 | AO10: July | AP10: 1 | AQ10: July
A11: 10 | B11: KEMAYORAN | C11: Supriantono Syahputra Wijaya | D11: ODRNO2607010136 | E11: 801PRS20260700850 | F11: Sales Agent (SA) | I11: MUHAMMAD RIZQY KEMAL | K11: 46204.638 | L11: 46212.333 | M11: Prospect Cancel | N11: Status Cancel Prospect | O11: USED | P11: DAIHATSU | Q11: 2011 | V11: not survey / not survey | W11: DKI | X11: Form Order - CF Bu Ana | Y11: Sales Agent (SA) | AA11: 1209191004890003 | AF11: b | AI11: ANTON RIA YANANTO-226215 | AK11: Cancel | AL11: SA | AM11: 1 | AN11: 2026 | AO11: July | AP11: 9 | AQ11: July
A12: 11 | B12: MANADO | C12: ANTONIUS WILLEM RAWUNG | D12: ODRNO2607010013 | E12: 828PRS20260700327 | F12: Sales Agent (SA) | I12: BATIN E TUWUILU | K12: 46204.353 | L12: 46212.333 | M12: Prospect Cancel | N12: Status Cancel Prospect | O12: USED | P12: NISSAN | Q12: 2021 | V12: not survey / not survey | W12: NON DKI | X12: Form Order - CF Bu Ana | Y12: Sales Agent (SA) | AA12: 7171090808760001 | AF12: db 1603 ag | AI12: PINGKAN IRENE HERMANUS-226129 | AK12: Cancel | AL12: SA | AM12: 1 | AN12: 2026 | AO12: July | AP12: 9 | AQ12: July
A13: 12 | B13: MANADO | C13: OLDI OLIVER ROMPIS | D13: ODRNO2607010014 | E13: 828PRS20260700328 | F13: Sales Agent (SA) | I13: BATIN E TUWUILU | K13: 46204.357 | L13: 46204.363 | M13: Prospect Cancel | N13: Status Cancel Prospect | O13: USED | P13: TOYOTA | Q13: 2015 | R13: automatic | V13: not survey / not survey | W13: NON DKI | X13: Form Order - CF Bu Ana | Y13: Sales Agent (SA) | AA13: 7171022110840001 | AF13: db 1827 aj | AI13: PINGKAN IRENE HERMANUS-226129 | AK13: Cancel | AL13: SA | AM13: 1 | AN13: 2026 | AO13: July | AP13: 1 | AQ13: July
A14: 13 | B14: MANADO | C14: JENDRY INDRO GEORGE KOJONGIAN | D14: ODRNO2607010017 | E14: 828PRS20260700329 | F14: Sales Agent (SA) | I14: BATIN E TUWUILU | K14: 46204.361 | L14: 46212.333 | M14: Prospect Cancel | N14: Status Cancel Prospect | O14: USED | P14: MITSUBISHI | Q14: 2019 | V14: not survey / not survey | W14: NON DKI | X14: Form Order - CF Bu Ana | Y14: Sales Agent (SA) | AA14: 7102132005920001 | AF14: db 1384 fe | AI14: PINGKAN IRENE HERMANUS-226129 | AK14: Cancel | AL14: SA | AM14: 1 | AN14: 2026 | AO14: July | AP14: 9 | AQ14: July
A15: 14 | B15: BANDUNG | C15: SANDI TRIYANA | D15: ODRNO2607020011 | E15: 813PRS20260705030 | F15: Sales Agent (SA) | I15: RAMDHAN FIRMANSYAH | K15: 46205.341 | L15: 46213.333 | M15: Prospect Cancel | N15: Status Cancel Prospect | O15: USED | P15: TOYOTA | Q15: 2016 | V15: not survey / not survey | W15: NON DKI | X15: Form Order - CF Bu Ana | Y15: Sales Agent (SA) | AA15: 3204132504940004 | AF15: 0 | AI15: ARIS YULIANSYAH HILMAN-126175 | AK15: Cancel | AL15: SA | AM15: 2 | AN15: 2026 | AO15: July | AP15: 10 | AQ15: July
A16: 15 | B16: BANDUNG | C16: RULY YULIANA | D16: ODRNO2607020031 | E16: 813PRS20260705037 | F16: Sales Agent (SA) | G16: 8131032600014 | H16: 813APP20260700009 | I16: RAMDHAN FIRMANSYAH | J16: PINJAMAN BU ANA | K16: 46205.365 | L16: 46206.446 | M16: Go Live | N16: Status Aplikasi sudah dilakukan Golive | O16: USED | P16: HONDA | Q16: 2013 | R16: automatic | S16: MUHLIS2 | V16: not survey / not survey | W16: NON DKI | X16: Form Order - CF Bu Ana | Y16: Sales Agent (SA) | Z16: PINJAMAN BU ANA PASSENGER SUMBER SALES AGENT PAKET MANTUL REBORN - MODAL USAHA | AA16: 3205191412940004 | AB16: 93600000 | AC16: MUHLIS2 | AD16: 46206 | AE16: D 1732 UM | AF16: 0 | AG16: MULTIGUNA JASA | AI16: DWI HARTO-226039 | AK16: Golive | AL16: SA | AM16: 2 | AN16: 2026 | AO16: July | AP16: 3 | AQ16: July
A17: 16 | B17: BANDUNG | C17: M IQBAL SUTISNA | D17: ODRNO2607020044 | E17: 813PRS20260705039 | F17: Sales Agent (SA) | G17: 8131022600013 | H17: 813APP20260700012 | I17: RAMDHAN FIRMANSYAH | J17: PINJAMAN BU ANA | K17: 46205.388 | L17: 46206.765 | M17: Go Live | N17: Status Aplikasi sudah dilakukan Golive | O17: USED | P17: SUZUKI | Q17: 2017 | R17: automatic | S17: MUHLIS2 | V17: not survey / not survey | W17: NON DKI | X17: Form Order - CF Bu Ana | Y17: Sales Agent (SA) | Z17: PINJAMAN BU ANA PASSENGER SUMBER SALES AGENT PAKET MANTUL REBORN | AA17: 6171032705920008 | AB17: 62050000 | AC17: MUHLIS2 | AD17: 46206 | AE17: D 1626 AFL | AF17: 0 | AG17: MULTIGUNA JASA | AI17: MIGIE NASEPUL QURBANI-126025 | AK17: Golive | AL17: SA | AM17: 2 | AN17: 2026 | AO17: July | AP17: 3 | AQ17: July
A18: 17 | B18: BANDUNG | C18: Elis Solihah | D18: ODRNO2607020095 | E18: 813PRS20260705044 | F18: Sales Agent (SA) | I18: RISKI DALNI | K18: 46205.465 | L18: 46213.333 | M18: Prospect Cancel | N18: Status Cancel Prospect | O18: USED | P18: TOYOTA | Q18: 2017 | V18: not survey / not survey | W18: NON DKI | X18: Form Order - CF Bu Ana | Y18: Sales Agent (SA) | AA18: 3204105012940006 | AF18: d | AI18: ANTON SURYA DININGRAT-126084 | AK18: Cancel | AL18: SA | AM18: 2 | AN18: 2026 | AO18: July | AP18: 10 | AQ18: July
A19: 18 | B19: BANJARMASIN | C19: gairil | D19: ODRNO2607020051 | E19: 825PRS20260700444 | F19: LandingPage | I19: Yandi Irawan | K19: 46205.399 | L19: 46213.333 | M19: Prospect Cancel | N19: Status Cancel Prospect | O19: USED | P19: TOYOTA | Q19: 2018 | V19: not survey / not survey | W19: NON DKI | X19: Form Order - CF Bu Ana | Y19: LandingPage | AA19: 6310042411750001 | AF19: 0 | AK19: Cancel | AL19: SA | AM19: 2 | AN19: 2026 | AO19: July | AP19: 10 | AQ19: July
A20: 19 | B20: BEKASI | C20: SURYANA | D20: ODRNO2607020138 | E20: 811PRS20260704469 | F20: Sales Agent (SA) | I20: KURNIAWAN ARIBOWO | K20: 46205.556 | L20: 46213.333 | M20: Prospect Cancel | N20: Status Cancel Prospect | O20: USED | P20: TOYOTA | Q20: 2018 | V20: not survey / not survey | W20: DKI | X20: Form Order - CF Bu Ana | Y20: Sales Agent (SA) | AA20: 3171040812790002 | AF20: b | AI20: AHMAD CHAIRUL-126059 | AK20: Cancel | AL20: SA | AM20: 2 | AN20: 2026 | AO20: July | AP20: 10 | AQ20: July
A21: 20 | B21: BEKASI | C21: MUHAMMAD SAIFUL BAHRI | D21: ODRNO2607020190 | E21: 811PRS20260704473 | F21: Sales Agent (SA) | I21: KURNIAWAN ARIBOWO | K21: 46205.666 | L21: 46213.333 | M21: Prospect Cancel | N21: Status Cancel Prospect | O21: USED | P21: DAIHATSU | Q21: 2016 | V21: not survey / not survey | W21: DKI | X21: Form Order - CF Bu Ana | Y21: Sales Agent (SA) | AA21: 3201372708980003 | AF21: b | AI21: RIFKI ARDIAN-126166 | AK21: Cancel | AL21: SA | AM21: 2 | AN21: 2026 | AO21: July | AP21: 10 | AQ21: July
A22: 21 | B22: BENGKULU | C22: hendra gunawan | D22: ODRNO2607020243 | E22: 809PRS20260701234 | F22: Sales Agent (SA) | I22: ADE CHANDRA PANE | K22: 46205.965 | L22: 46214.333 | M22: Prospect Cancel | N22: Status Cancel Prospect | O22: USED | P22: TOYOTA | Q22: 2020 | V22: not survey / not survey | W22: NON DKI | X22: Form Order - CF Bu Ana | Y22: Sales Agent (SA) | AA22: 1707081212900001 | AF22: bd 4959 er | AI22: JONI PRANATA-126403 | AK22: Cancel | AL22: SA | AM22: 2 | AN22: 2026 | AO22: July | AP22: 11 | AQ22: July
A23: 22 | B23: DENPASAR | C23: I WAYAN WARGITA | D23: ODRNO2607020069 | E23: 821PRS20260700723 | F23: LandingPage | I23: I MADE BAGUS PUTRA WIRAPASTIKA S I KOM | K23: 46205.423 | L23: 46213.333 | M23: Prospect Cancel | N23: Status Cancel Prospect | O23: USED | P23: TOYOTA | Q23: 2014 | V23: not survey / not survey | W23: NON DKI | X23: Form Order - CF Bu Ana | Y23: LandingPage | AA23: 5171021612750004 | AF23: DK | AK23: Cancel | AL23: SA | AM23: 2 | AN23: 2026 | AO23: July | AP23: 10 | AQ23: July
A24: 23 | B24: LAMPUNG | C24: suranti | D24: ODRNO2607020166 | E24: 810PRS20260700660 | F24: Sales Agent (SA) | I24: AZWAN | K24: 46205.626 | L24: 46213.333 | M24: Prospect Cancel | N24: Status Cancel Prospect | O24: USED | P24: TOYOTA | Q24: 2018 | V24: not survey / not survey | W24: NON DKI | X24: Form Order - CF Bu Ana | Y24: Sales Agent (SA) | AA24: 1801055011850012 | AF24: 00000 | AI24: SUHENDRI SETIAWAN-126057 | AK24: Cancel | AL24: SA | AM24: 2 | AN24: 2026 | AO24: July | AP24: 10 | AQ24: July
A25: 24 | B25: LAMPUNG | C25: nyoman kukuh rianto | D25: ODRNO2607020197 | E25: 810PRS20260700661 | F25: Sales Agent (SA) | H25: 810APP20260700016 | I25: AZWAN | J25: PINJAMAN BU ANA | K25: 46205.693 | L25: 46216.712 | M25: Return Handling | N25: Status Aplikasi sedang diajukan RETURN oleh Komite Kredit | O25: USED | P25: TOYOTA | Q25: 2018 | R25: muhammad.hamedan | S25: MUHLIS2 | V25: not survey / not survey | W25: NON DKI | X25: Form Order - CF Bu Ana | Y25: Sales Agent (SA) | Z25: PINJAMAN BU ANA PASSENGER SUMBER SALES AGENT PAKET SANTUY REBORN - MODAL USAHA | AA25: 1801070109860003 | AC25: MUHLIS2 | AD25: 46216 | AE25: 0000 | AF25: 0000 | AG25: 99910000 | AI25: TOMMI CHINTYO GELLI-126008 | AK25: In Proses | AL25: SA | AM25: 2 | AN25: 2026 | AO25: July | AP25: 13 | AQ25: July
A26: 25 | B26: MEDAN DUA | C26: ERWIN CANDRA RANGKUTI | D26: ODRNO2607020021 | E26: 839PRS20260700863 | F26: Sales Agent (SA) | H26: 839APP20260700003 | I26: WASTO SIHOMBING | J26: PINJAMAN BU ANA | K26: 46205.354 | L26: 46206.72 | M26: Return Handling | N26: Status Aplikasi sedang diajukan RETURN oleh Komite Kredit | O26: USED | P26: TOYOTA | Q26: 2022 | R26: muhammad.hamedan | S26: MUHLIS2 | V26: not survey / not survey | W26: NON DKI | X26: Form Order - CF Bu Ana | Y26: Sales Agent (SA) | Z26: PINJAMAN BU ANA PASSENGER SUMBER SALES AGENT PAKET MANJIW REBORN - MODAL USAHA | AA26: 1271211006890001 | AC26: MUHLIS2 | AD26: 46206 | AE26: 0 | AF26: 0 | AG26: 99910000 | AI26: FANNY TRI WAHYUNI TANJUNG-126080 | AK26: In Proses | AL26: SA | AM26: 2 | AN26: 2026 | AO26: July | AP26: 3 | AQ26: July
A27: 26 | B27: MEDAN DUA | C27: WAGIMAN | D27: ODRNO2607020152 | E27: 839PRS20260700865 | F27: Sales Agent (SA) | I27: WASTO SIHOMBING | K27: 46205.585 | L27: 46213.333 | M27: Prospect Cancel | N27: Status Cancel Prospect | O27: USED | P27: TOYOTA | Q27: 2021 | V27: not survey / not survey | W27: NON DKI | X27: Form Order - CF Bu Ana | Y27: Sales Agent (SA) | AA27: 1207261806690009 | AF27: 0 | AI27: HERRY BUDIANTO MANULLANG-126401 | AK27: Cancel | AL27: SA | AM27: 2 | AN27: 2026 | AO27: July | AP27: 10 | AQ27: July
A28: 27 | B28: PEKANBARU | C28: JUHELDI PRATAMA | D28: ODRNO2607020159 | E28: 805PRS20260702478 | F28: Sales Agent (SA) | I28: MUHAMMAD RIDWAN | K28: 46205.619 | L28: 46213.333 | M28: Prospect Cancel | N28: Status Cancel Prospect | O28: USED | P28: TOYOTA | Q28: 2022 | V28: not survey / not survey | W28: NON DKI | X28: Form Order - CF Bu Ana | Y28: Sales Agent (SA) | AA28: 1403030406960557 | AF28: 0 | AI28: WIWIN PRASETYA-126121 | AK28: Cancel | AL28: SA | AM28: 2 | AN28: 2026 | AO28: July | AP28: 10 | AQ28: July
A29: 28 | B29: SAMARINDA | C29: MATHIUS JEFRIE | D29: ODRNO2607020098 | E29: 823PRS20260700356 | F29: Telemarketing Program | I29: BAYU SAPUTRA | K29: 46205.471 | L29: 46213.333 | M29: Prospect Cancel | N29: Status Cancel Prospect | O29: USED | P29: TOYOTA | Q29: 2021 | V29: not survey / not survey | W29: NON DKI | X29: Form Order - CF Bu Ana | Y29: Telemarketing Program | AA29: 6408042608930002 | AF29: 0 | AK29: Cancel | AL29: Tele | AM29: 2 | AN29: 2026 | AO29: July | AP29: 10 | AQ29: July
A30: 29 | B30: SURABAYA SATU | C30: dimas endar christa pahlawan | D30: ODRNO2607020085 | E30: 819PRS20260700993 | F30: Sales Agent (SA) | G30: 8191022600009 | H30: 819APP20260700006 | I30: PONDRA PUJIONO | J30: PINJAMAN BU ANA | K30: 46205.45 | L30: 46211.27 | M30: Go Live | N30: Status Aplikasi sudah dilakukan Golive | O30: USED | P30: FORD | Q30: 2014 | R30: anggun.wibowo | S30: MUHLIS2 | V30: not survey / not survey | W30: NON DKI | X30: Form Order - CF Bu Ana | Y30: Sales Agent (SA) | Z30: PINJAMAN BU ANA PASSENGER SUMBER SALES AGENT PAKET SANTUY REBORN | AA30: 3515162312860002 | AB30: 64800060 | AC30: MUHLIS2 | AD30: 46209 | AE30: W 1432 QG | AF30: xxxxxx | AG30: MULTIGUNA JASA | AI30: DWI HARTO-226039 | AK30: Golive | AL30: SA | AM30: 2 | AN30: 2026 | AO30: July | AP30: 8 | AQ30: July
A31: 30 | B31: ALAM SUTERA | C31: MOHAMAD NGAFIF | D31: ODRNO2607030054 | E31: 838PRS20260702417 | F31: Sales Agent (SA) | G31: 8381032600024 | H31: 838APP20260700015 | I31: IBRAHIM AZIZ | J31: SALES AGENT DUMMY | K31: 46206.424 | L31: 46210.48 | M31: Go Live | N31: Status Aplikasi sudah dilakukan Golive | O31: USED | P31: TOYOTA | Q31: 2025 | R31: automatic | S31: MUHLIS2 | V31: not survey / not survey | W31: DKI | X31: Form Order - CF Bu Ana | Y31: Sales Agent (SA) | Z31: PINJAMAN BU ANA PASSENGER SUMBER SALES AGENT PAKET SANTUY REBORN - MODAL USAHA | AA31: 3603180309710003 | AB31: 174939500 | AC31: MUHLIS2 | AD31: 46209 | AE31: A 1450 VUA | AF31: A 1450 VUA | AG31: MULTIGUNA JASA | AI31: DONNIE PRASTIYO-526010 | AK31: Golive | AL31: SA | AM31: 3 | AN31: 2026 | AO31: July | AP31: 7 | AQ31: July
A32: 31 | B32: ALAM SUTERA | C32: ABID HAIKAL AFIFI | D32: ODRNO2607030055 | E32: 838PRS20260702418 | F32: Sales Agent (SA) | I32: IBRAHIM AZIZ | K32: 46206.427 | L32: 46206.442 | M32: Prospect Cancel | N32: Status Cancel Prospect | O32: USED | P32: TOYOTA | Q32: 2025 | R32: automatic | V32: not survey / not survey | W32: DKI | X32: Form Order - CF Bu Ana | Y32: Sales Agent (SA) | AA32: 3603180503050001 | AF32: A 1450 VUA | AI32: DONNIE PRASTIYO-526010 | AK32: Cancel | AL32: SA | AM32: 3 | AN32: 2026 | AO32: July | AP32: 3 | AQ32: July
A33: 32 | B33: BANDUNG | C33: Ratna Komala | D33: ODRNO2607030016 | E33: 813PRS20260705061 | F33: Sales Agent (SA) | I33: RISKI DALNI | K33: 46206.354 | L33: 46206.431 | M33: Prospect Cancel | N33: Status Cancel Prospect | O33: USED | P33: TOYOTA | Q33: 2011 | R33: boyke.nugraha | V33: not survey / not survey | W33: NON DKI | X33: Form Order - CF Bu Ana | Y33: Sales Agent (SA) | AA33: 3203074302760012 | AF33: d | AI33: HERNA SIGIRO-126305 | AK33: Cancel | AL33: SA | AM33: 3 | AN33: 2026 | AO33: July | AP33: 3 | AQ33: July
A34: 33 | B34: BANDUNG | C34: MUHAMAD RIVAN APRIANTO | D34: ODRNO2607030062 | E34: 813PRS20260705068 | F34: Sales Agent (SA) | I34: RAMDHAN FIRMANSYAH | K34: 46206.437 | L34: 46214.333 | M34: Prospect Cancel | N34: Status Cancel Prospect | O34: USED | P34: HONDA | Q34: 2015 | V34: not survey / not survey | W34: NON DKI | X34: Form Order - CF Bu Ana | Y34: Sales Agent (SA) | AA34: 3273222604930001 | AF34: E 1750 NE | AI34: FENDI RUSNANDI SH-126315 | AK34: Cancel | AL34: SA | AM34: 3 | AN34: 2026 | AO34: July | AP34: 11 | AQ34: July
A35: 34 | B35: BANDUNG | C35: DENI PARDANI | D35: ODRNO2607030100 | E35: 813PRS20260705075 | F35: Sales Agent (SA) | I35: RAMDHAN FIRMANSYAH | K35: 46206.535 | L35: 46214.333 | M35: Prospect Cancel | N35: Status Cancel Prospect | O35: USED | P35: NISSAN | Q35: 2011 | V35: not survey / not survey | W35: NON DKI | X35: Form Order - CF Bu Ana | Y35: Sales Agent (SA) | AA35: 3204290605820004 | AF35: 0 | AI35: ARIS YULIANSYAH HILMAN-126175 | AK35: Cancel | AL35: SA | AM35: 3 | AN35: 2026 | AO35: July | AP35: 11 | AQ35: July
A36: 35 | B36: BANDUNG | C36: Getty Amanu Suciati | D36: ODRNO2607030135 | E36: 813PRS20260705080 | F36: Sales Agent (SA) | I36: RISKI DALNI | K36: 46206.588 | L36: 46215.333 | M36: Prospect Cancel | N36: Status Cancel Prospect | O36: USED | P36: HONDA | Q36: 2016 | V36: not survey / not survey | W36: NON DKI | X36: Form Order - CF Bu Ana | Y36: Sales Agent (SA) | AA36: 3204105904790002 | AF36: d | AI36: HANAN MULYANA-0626048 | AK36: Cancel | AL36: SA | AM36: 3 | AN36: 2026 | AO36: July | AP36: 12 | AQ36: July
A37: 36 | B37: BANDUNG | C37: Alfi | D37: ODRNO2607030141 | E37: 813PRS20260705082 | F37: Sales Agent (SA) | I37: RISKI DALNI | K37: 46206.601 | L37: 46214.333 | M37: Prospect Cancel | N37: Status Cancel Prospect | O37: USED | P37: DAIHATSU | Q37: 2020 | V37: not survey / not survey | W37: NON DKI | X37: Form Order - CF Bu Ana | Y37: Sales Agent (SA) | AA37: 3211150207890006 | AF37: d | AI37: REZA KURNIAWAN-0626057 | AK37: Cancel | AL37: SA | AM37: 3 | AN37: 2026 | AO37: July | AP37: 11 | AQ37: July
A38: 37 | B38: BATAM | C38: nur samsidar | D38: ODRNO2607030088 | E38: 806PRS20260702006 | F38: Sales Agent (SA) | I38: ANDINA WAHYUNI PUSPITASARI | K38: 46206.49 | L38: 46206.507 | M38: Prospect Cancel | N38: Status Cancel Prospect | O38: USED | P38: SUZUKI | Q38: 2022 | R38: automatic | V38: not survey / not survey | W38: NON DKI | X38: Form Order - CF Bu Ana | Y38: Sales Agent (SA) | AA38: 2171026004829002 | AF38: BP1486RD | AI38: FAHREZA PERKASA ALAM-0726005 | AK38: Cancel | AL38: SA | AM38: 3 | AN38: 2026 | AO38: July | AP38: 3 | AQ38: July
A39: 38 | B39: BEKASI | C39: m imron andrianto | D39: ODRNO2607030102 | E39: 811PRS20260704491 | F39: Sales Agent (SA) | I39: KURNIAWAN ARIBOWO | K39: 46206.538 | L39: 46214.333 | M39: Prospect Cancel | N39: Status Cancel Prospect | O39: USED | P39: TOYOTA | Q39: 2022 | V39: not survey / not survey | W39: DKI | X39: Form Order - CF Bu Ana | Y39: Sales Agent (SA) | AA39: 3174071306660003 | AF39: b | AI39: AHMAD CHAIRUL-126059 | AK39: Cancel | AL39: SA | AM39: 3 | AN39: 2026 | AO39: July | AP39: 11 | AQ39: July
A40: 39 | B40: BEKASI | C40: arya geni utama | D40: ODRNO2607030155 | E40: 811PRS20260704501 | F40: Sales Agent (SA) | I40: KURNIAWAN ARIBOWO | K40: 46206.627 | L40: 46215.333 | M40: Prospect Cancel | N40: Status Cancel Prospect | O40: USED | P40: HONDA | Q40: 2019 | V40: not survey / not survey | W40: DKI | X40: Form Order - CF Bu Ana | Y40: Sales Agent (SA) | AA40: 3216061711880002 | AF40: b | AI40: ALEXANDER MARCEL-326017 | AK40: Cancel | AL40: SA | AM40: 3 | AN40: 2026 | AO40: July | AP40: 12 | AQ40: July
...
